<mujoco model="ur5e">
  <compiler angle="radian" autolimits="true"/>
  <statistic meansize="0.170788" extent="1.04615" center="0.386431 0.0886669 0.162989"/>
  <asset>
    <mesh name="base" file="base.stl"/>
    <mesh name="shoulder" file="shoulder.stl"/>
    <mesh name="upperarm" file="upperarm.stl"/>
    <mesh name="forearm" file="forearm.stl"/>
    <mesh name="wrist1" file="wrist1.stl"/>
    <mesh name="wrist2" file="wrist2.stl"/>
    <mesh name="wrist3" file="wrist3.stl"/>
  </asset>
  <worldbody>
    <geom type="mesh" rgba="0.7 0.7 0.7 1" mesh="base"/>
    <body name="shoulder_link" pos="0 0 0.163">
      <inertial pos="0 0 0" mass="3.7" diaginertia="0.0102675 0.0102675 0.00666"/>
      <joint name="shoulder_pan_joint" pos="0 0 0" axis="0 0 1" range="-3.1415 3.1415"/>
      <geom type="mesh" rgba="0.7 0.7 0.7 1" mesh="shoulder"/>
      <body name="upper_arm_link" pos="0 0.138 0" quat="0.707107 0 0.707107 0">
        <inertial pos="0 0 0.2125" mass="8.393" diaginertia="0.133886 0.133886 0.0151074"/>
        <joint name="shoulder_lift_joint" pos="0 0 0" axis="0 1 0" range="-3.1415 3.1415"/>
        <geom type="mesh" rgba="0.7 0.7 0.7 1" mesh="upperarm"/>
        <body name="forearm_link" pos="0 -0.131 0.425">
          <inertial pos="0 0 0.196" mass="2.275" diaginertia="0.0311796 0.0311796 0.004095"/>
          <joint name="elbow_joint" pos="0 0 0" axis="0 1 0" range="-3.14159 3.14159"/>
          <geom type="mesh" rgba="0.7 0.7 0.7 1" mesh="forearm"/>
          <body name="wrist_1_link" pos="0 0 0.392" quat="0.707107 0 0.707107 0">
            <inertial pos="0 0.127 0" mass="1.219" diaginertia="0.0025599 0.0025599 0.0021942"/>
            <joint name="wrist_1_joint" pos="0 0 0" axis="0 1 0" range="-6.28319 6.28319"/>
            <geom type="mesh" rgba="0.7 0.7 0.7 1" mesh="wrist1"/>
            <body name="wrist_2_link" pos="0 0.127 0">
              <inertial pos="0 0 0.1" mass="1.219" diaginertia="0.0025599 0.0025599 0.0021942"/>
              <joint name="wrist_2_joint" pos="0 0 0" axis="0 0 1" range="-6.28319 6.28319"/>
              <geom type="mesh" rgba="0.7 0.7 0.7 1" mesh="wrist2"/>
              <body name="wrist_3_link" pos="0 0 0.1">
                <inertial pos="0 0.0771683 0" quat="0.707107 0 0 0.707107" mass="0.1889" diaginertia="0.000132134 9.90863e-05 9.90863e-05"/>
                <joint name="wrist_3_joint" pos="0 0 0" axis="0 1 0" range="-6.28319 6.28319"/>
                <geom type="mesh" rgba="0.7 0.7 0.7 1" mesh="wrist3"/>
                <geom size="0.005 0.005 0.005" pos="0 0.09 0" quat="0.707107 0 0 0.707107" type="box"/>
              </body>
            </body>
          </body>
        </body>
      </body>
    </body>
  </worldbody>
  <actuator>
        <general  name="shoulder_pan" joint="shoulder_pan_joint"/>
        <general  name="shoulder_lift" joint="shoulder_lift_joint"/>
        <general  name="elbow" joint="elbow_joint"/>
        <general  name="wrist_1" joint="wrist_1_joint"/>
        <general  name="wrist_2" joint="wrist_2_joint"/>
        <general  name="wrist_3" joint="wrist_3_joint"/>
  </actuator>
  <keyframe>
        <key name="home" qpos="1.57 -1.5708 1.5708 3.14 -1.5708 1.57" ctrl="0 -1.5708 1.5708 3.14 -1.5708 0"/>
  </keyframe>
</mujoco>
